Traceback (most recent call last):
  File "/home/amy/.virtualenvs/venv_birth_outcomes_book/lib/python3.10/site-packages/jupyter_cache/executors/utils.py", line 58, in single_nb_execution
    executenb(
  File "/home/amy/.virtualenvs/venv_birth_outcomes_book/lib/python3.10/site-packages/nbclient/client.py", line 1314, in execute
    return NotebookClient(nb=nb, resources=resources, km=km, **kwargs).execute()
  File "/home/amy/.virtualenvs/venv_birth_outcomes_book/lib/python3.10/site-packages/jupyter_core/utils/__init__.py", line 165, in wrapped
    return loop.run_until_complete(inner)
  File "/usr/lib/python3.10/asyncio/base_events.py", line 649, in run_until_complete
    return future.result()
  File "/home/amy/.virtualenvs/venv_birth_outcomes_book/lib/python3.10/site-packages/nbclient/client.py", line 709, in async_execute
    await self.async_execute_cell(
  File "/home/amy/.virtualenvs/venv_birth_outcomes_book/lib/python3.10/site-packages/nbclient/client.py", line 1062, in async_execute_cell
    await self._check_raise_for_error(cell, cell_index, exec_reply)
  File "/home/amy/.virtualenvs/venv_birth_outcomes_book/lib/python3.10/site-packages/nbclient/client.py", line 918, in _check_raise_for_error
    raise CellExecutionError.from_cell_and_msg(cell, exec_reply_content)
nbclient.exceptions.CellExecutionError: An error occurred while executing the following cell:
------------------
formula = "log_wage ~ years_of_schooling + C(state_of_birth) + C(year_of_birth) + C(quarter_of_birth)"
ols = IV2SLS.from_formula(formula, data=data).fit()
parse(ols)
------------------


[0;31m---------------------------------------------------------------------------[0m
[0;31mNameError[0m                                 Traceback (most recent call last)
Cell [0;32mIn[4], line 3[0m
[1;32m      1[0m formula [38;5;241m=[39m [38;5;124m"[39m[38;5;124mlog_wage ~ years_of_schooling + C(state_of_birth) + C(year_of_birth) + C(quarter_of_birth)[39m[38;5;124m"[39m
[1;32m      2[0m ols [38;5;241m=[39m IV2SLS[38;5;241m.[39mfrom_formula(formula, data[38;5;241m=[39mdata)[38;5;241m.[39mfit()
[0;32m----> 3[0m [43mparse[49m(ols)

[0;31mNameError[0m: name 'parse' is not defined

